Workbook

Sheet Datos Participantes
A1: ID_Participante | B1: DNI | C1: Nombres | D1: Apellidos | E1: Fecha_Prueba | F1: Edad | G1: Sexo | H1: Nivel_TEA | I1: Institucion | J1: Ciudad | K1: Distrito | L1: Sesion | M1: Sesiones_Completadas | N1: Duracion_Minutos | O1: Emociones_Correctas | P1: Emociones_Incorrectas | Q1: Precision_Porcentaje | R1: Tiempo_Respuesta_Promedio_Seg | S1: Nivel_Dificultad | T1: Intentos_Por_Emocion | U1: Porcentaje_Predominante | V1: Emocion_Predominante | W1: Satisfaccion_Usuario | X1: Facilidad_Uso | Y1: Continuaria_Usando | Z1: Observaciones
A2: P001 | B2: 72845123 | C2: Carlos José | D2: Ramírez Sánchez | E2: 2025-11-15 | F2: =RANDBETWEEN(1,18) -> 15 | G2: M | H2: TEA Nivel 1 | I2: Centro TEA Tumbes | J2: Tumbes | K2: Tumbes | L2: 1 | M2: 1 | N2: 42 | O2: 15 | P2: 4 | Q2: =O2/(O2+P2)*100 -> 78.947368 | R2: 5 | S2: Fácil | T2: 3.3 | U2: 60.9 | V2: Feliz | W2: 4 | X2: 3 | Y2: No | Z2: Excelente progreso en reconocimiento emocional
A3: P002 | B3: 71234567 | C3: María Elena | D3: Torres Vega | E3: 2025-10-29 | F3: =RANDBETWEEN(1,18) -> 5 | G3: F | H3: Síndrome de Asperger | I3: Centro TEA Corrales | J3: Tumbes | K3: Corrales | L3: 1 | M3: 1 | N3: 45 | O3: 15 | P3: 8 | Q3: =O3/(O3+P3)*100 -> 65.217391 | R3: 4.5 | S3: Medio | T3: 2.4 | U3: 69.2 | V3: Neutral | W3: 5 | X3: 4 | Y3: Sí
A4: P003 | B4: 74556789 | C4: Jocelyn Luisa | D4: Mendoza Castro | E4: 2025-11-05 | F4: =RANDBETWEEN(1,18) -> 11 | G4: F | H4: TEA Nivel 2 | I4: Centro TEA Zarumilla | J4: Tumbes | K4: Zarumilla | L4: 1 | M4: 3 | N4: 35 | O4: 8 | P4: 4 | Q4: =O4/(O4+P4)*100 -> 66.666667 | R4: 4.7 | S4: Medio | T4: 2.7 | U4: 76.2 | V4: Enojado | W4: 5 | X4: 4 | Y4: No | Z4: Muy motivado con el formato de juego
A5: P003 | B5: 74556789 | C5: Jocelyn Luisa | D5: Mendoza Castro | E5: 2025-10-29 | F5: =RANDBETWEEN(1,18) -> 15 | G5: F | H5: TEA Nivel 2 | I5: Centro TEA Zarumilla | J5: Tumbes | K5: Zarumilla | L5: 2 | M5: 3 | N5: 42 | O5: 9 | P5: 8 | Q5: =O5/(O5+P5)*100 -> 52.941176 | R5: 6 | S5: Medio | T5: 1.7 | U5: 62.2 | V5: Enojado | W5: 4 | X5: 4 | Y5: Sí | Z5: Mostró gran interés en la actividad
A6: P003 | B6: 74556789 | C6: Jocelyn Luisa | D6: Mendoza Castro | E6: 2025-10-31 | F6: =RANDBETWEEN(1,18) -> 14 | G6: F | H6: TEA Nivel 2 | I6: Centro TEA Zarumilla | J6: Tumbes | K6: Zarumilla | L6: 3 | M6: 3 | N6: 39 | O6: 14 | P6: 8 | Q6: =O6/(O6+P6)*100 -> 63.636364 | R6: 5.2 | S6: Difícil | T6: 1.6 | U6: 66.5 | V6: Feliz | W6: 5 | X6: 5 | Y6: Sí | Z6: Pidió repetir algunos ejercicios
A7: P004 | B7: 74567890 | C7: Ana Patricia | D7: García Flores | E7: 2025-11-05 | F7: =RANDBETWEEN(1,18) -> 15 | G7: F | H7: TEA Nivel 1 | I7: Centro TEA Tumbes | J7: Tumbes | K7: Tumbes | L7: 1 | M7: 2 | N7: 38 | O7: 12 | P7: 3 | Q7: =O7/(O7+P7)*100 -> 80 | R7: 5 | S7: Fácil | T7: 1.6 | U7: 44.8 | V7: Enojado | W7: 5 | X7: 3 | Y7: Sí | Z7: Mostró gran interés en la actividad
A8: P004 | B8: 74567890 | C8: Ana Patricia | D8: García Flores | E8: 2025-11-14 | F8: =RANDBETWEEN(1,18) -> 5 | G8: F | H8: TEA Nivel 1 | I8: Centro TEA Tumbes | J8: Tumbes | K8: Tumbes | L8: 2 | M8: 2 | N8: 32 | O8: 18 | P8: 2 | Q8: =O8/(O8+P8)*100 -> 90 | R8: 8.1 | S8: Medio | T8: 3.2 | U8: 49 | V8: Triste | W8: 5 | X8: 5 | Y8: Sí
A9: P005 | B9: 72678901 | C9: Pedro Andrés | D9: Huamán Ruiz | E9: 2025-11-05 | F9: =RANDBETWEEN(1,18) -> 11 | G9: M | H9: TEA Nivel 3 | I9: Centro TEA San Jacinto | J9: Tumbes | K9: San Jacinto | L9: 1 | M9: 1 | N9: 29 | O9: 11 | P9: 13 | Q9: =O9/(O9+P9)*100 -> 45.833333 | R9: 4.4 | S9: Medio | T9: 2.6 | U9: 73.2 | V9: Neutral | W9: 4 | X9: 5 | Y9: Sí | Z9: Pidió repetir algunos ejercicios
A10: P006 | B10: 71789012 | C10: Lucia Fernanda | D10: Pérez Morales | E10: 2025-11-13 | F10: =RANDBETWEEN(1,18) -> 3 | G10: F | H10: Síndrome de Asperger | I10: Centro TEA Tumbes | J10: Tumbes | K10: Tumbes | L10: 1 | M10: 1 | N10: 40 | O10: 15 | P10: 4 | Q10: =O10/(O10+P10)*100 -> 78.947368 | R10: 6.4 | S10: Medio | T10: 1.9 | U10: 53.9 | V10: Enojado | W10: 4 | X10: 4 | Y10: Sí | Z10: Necesita más práctica con emociones sutiles
A11: P007 | B11: 73890123 | C11: Roberto Carlos | D11: Díaz Quispe | E11: 2025-11-03 | F11: =RANDBETWEEN(1,18) -> 12 | G11: M | H11: TEA Nivel 2 | I11: Centro TEA Aguas Verdes | J11: Zarumilla | K11: Aguas Verdes | L11: 1 | M11: 1 | N11: 39 | O11: 10 | P11: 9 | Q11: =O11/(O11+P11)*100 -> 52.631579 | R11: 8.1 | S11: Medio | T11: 2.2 | U11: 73.7 | V11: Disgustado | W11: 5 | X11: 5 | Y11: Sí | Z11: Se distrajo en algunos momentos
A12: P008 | B12: 74901234 | C12: Carmen Rosa | D12: Velásquez Núñez | E12: 2025-10-29 | F12: =RANDBETWEEN(1,18) -> 4 | G12: F | H12: TEA Nivel 1 | I12: Centro TEA Tumbes | J12: Tumbes | K12: Tumbes | L12: 1 | M12: 2 | N12: 37 | O12: 16 | P12: 3 | Q12: =O12/(O12+P12)*100 -> 84.210526 | R12: 7.4 | S12: Medio | T12: 2.4 | U12: 83.3 | V12: Feliz | W12: 5 | X12: 4 | Y12: No | Z12: Buena concentración durante toda la sesión
A13: P008 | B13: 74901234 | C13: Carmen Rosa | D13: Velásquez Núñez | E13: 2025-11-14 | F13: =RANDBETWEEN(1,18) -> 11 | G13: F | H13: TEA Nivel 1 | I13: Centro TEA Tumbes | J13: Tumbes | K13: Tumbes | L13: 2 | M13: 2 | N13: 28 | O13: 15 | P13: 4 | Q13: =O13/(O13+P13)*100 -> 78.947368 | R13: 8.1 | S13: Medio | T13: 2.9 | U13: 85 | V13: Triste | W13: 3 | X13: 3 | Y13: Sí
A14: P009 | B14: 72012345 | C14: Miguel Ángel | D14: Salazar Gómez | E14: 2025-11-13 | F14: =RANDBETWEEN(1,18) -> 2 | G14: M | H14: TEA Nivel 2 | I14: Centro TEA La Cruz | J14: Tumbes | K14: La Cruz | L14: 1 | M14: 2 | N14: 27 | O14: 14 | P14: 7 | Q14: =O14/(O14+P14)*100 -> 66.666667 | R14: 4.8 | S14: Difícil | T14: 3.4 | U14: 72.2 | V14: Disgustado | W14: 5 | X14: 5 | Y14: Sí | Z14: Mostró gran interés en la actividad
A15: P009 | B15: 72012345 | C15: Miguel Ángel | D15: Salazar Gómez | E15: 2025-11-10 | F15: =RANDBETWEEN(1,18) -> 3 | G15: M | H15: TEA Nivel 2 | I15: Centro TEA La Cruz | J15: Tumbes | K15: La Cruz | L15: 2 | M15: 2 | N15: 28 | O15: 13 | P15: 10 | Q15: =O15/(O15+P15)*100 -> 56.521739 | R15: 7 | S15: Difícil | T15: 1.5 | U15: 68.9 | V15: Enojado | W15: 4 | X15: 5 | Y15: Sí | Z15: Buena concentración durante toda la sesión
A16: P010 | B16: 71123456 | C16: Sandra Milena | D16: Rojas Paredes | E16: 2025-11-07 | F16: =RANDBETWEEN(1,18) -> 3 | G16: F | H16: Síndrome de Asperger | I16: Centro TEA Tumbes | J16: Tumbes | K16: Tumbes | L16: 1 | M16: 3 | N16: 41 | O16: 11 | P16: 7 | Q16: =O16/(O16+P16)*100 -> 61.111111 | R16: 7.5 | S16: Medio | T16: 2.3 | U16: 47.6 | V16: Enojado | W16: 5 | X16: 5 | Y16: Sí
A17: P010 | B17: 71123456 | C17: Sandra Milena | D17: Rojas Paredes | E17: 2025-11-06 | F17: =RANDBETWEEN(1,18) -> 13 | G17: F | H17: Síndrome de Asperger | I17: Centro TEA Tumbes | J17: Tumbes | K17: Tumbes | L17: 2 | M17: 3 | N17: 43 | O17: 15 | P17: 5 | Q17: =O17/(O17+P17)*100 -> 75 | R17: 6 | S17: Medio | T17: 2.4 | U17: 52.5 | V17: Neutral | W17: 3 | X17: 3 | Y17: Sí | Z17: Mostró gran interés en la actividad
A18: P010 | B18: 71123456 | C18: Sandra Milena | D18: Rojas Paredes | E18: 2025-11-11 | F18: =RANDBETWEEN(1,18) -> 11 | G18: F | H18: Síndrome de Asperger | I18: Centro TEA Tumbes | J18: Tumbes | K18: Tumbes | L18: 3 | M18: 3 | N18: 34 | O18: 10 | P18: 3 | Q18: =O18/(O18+P18)*100 -> 76.923077 | R18: 5.5 | S18: Medio | T18: 1.6 | U18: 83.9 | V18: Neutral | W18: 5 | X18: 5 | Y18: Sí | Z18: Pidió repetir algunos ejercicios
A19: P011 | B19: 72345677 | C19: Daniel Eduardo | D19: Chávez Silupu | E19: 2025-11-05 | F19: =RANDBETWEEN(1,18) -> 18 | G19: M | H19: TEA Nivel 3 | I19: Centro TEA Pampas de Hospital | J19: Tumbes | K19: Pampas de Hospital | L19: 1 | M19: 1 | N19: 38 | O19: 7 | P19: 12 | Q19: =O19/(O19+P19)*100 -> 36.842105 | R19: 4.6 | S19: Difícil | T19: 3.5 | U19: 58.2 | V19: Feliz | W19: 5 | X19: 3 | Y19: Sí | Z19: Muy motivado con el formato de juego
A20: P012 | B20: 74345678 | C20: Gabriela Isabel | D20: Castillo Reyes | E20: 2025-10-30 | F20: =RANDBETWEEN(1,18) -> 2 | G20: F | H20: TEA Nivel 1 | I20: Centro TEA Corrales | J20: Tumbes | K20: Corrales | L20: 1 | M20: 2 | N20: 26 | O20: 16 | P20: 2 | Q20: =O20/(O20+P20)*100 -> 88.888889 | R20: 5.5 | S20: Medio | T20: 1.8 | U20: 53.7 | V20: Neutral | W20: 4 | X20: 4 | Y20: Sí | Z20: Muy motivado con el formato de juego
A21: P012 | B21: 74345678 | C21: Gabriela Isabel | D21: Castillo Reyes | E21: 2025-11-11 | F21: =RANDBETWEEN(1,18) -> 2 | G21: F | H21: TEA Nivel 1 | I21: Centro TEA Corrales | J21: Tumbes | K21: Corrales | L21: 2 | M21: 2 | N21: 34 | O21: 13 | P21: 2 | Q21: =O21/(O21+P21)*100 -> 86.666667 | R21: 5.7 | S21: Fácil | T21: 3.2 | U21: 41.7 | V21: Feliz | W21: 5 | X21: 5 | Y21: No | Z21: Pidió repetir algunos ejercicios
A22: P013 | B22: 72456789 | C22: Fernando José | D22: Vargas Medina | E22: 2025-11-09 | F22: =RANDBETWEEN(1,18) -> 2 | G22: M | H22: TEA Nivel 2 | I22: Centro TEA Zarumilla | J22: Tumbes | K22: Zarumilla | L22: 1 | M22: 2 | N22: 41 | O22: 10 | P22: 8 | Q22: =O22/(O22+P22)*100 -> 55.555556 | R22: 7.6 | S22: Difícil | T22: 1.2 | U22: 53.3 | V22: Triste | W22: 4 | X22: 5 | Y22: No | Z22: Necesita más práctica con emociones sutiles
A23: P013 | B23: 72456789 | C23: Fernando José | D23: Vargas Medina | E23: 2025-11-10 | F23: =RANDBETWEEN(1,18) -> 16 | G23: M | H23: TEA Nivel 2 | I23: Centro TEA Zarumilla | J23: Tumbes | K23: Zarumilla | L23: 2 | M23: 2 | N23: 35 | O23: 8 | P23: 8 | Q23: =O23/(O23+P23)*100 -> 50 | R23: 4.8 | S23: Difícil | T23: 2.7 | U23: 68.6 | V23: Enojado | W23: 5 | X23: 3 | Y23: No | Z23: Requirió apoyo adicional del terapeuta
A24: P014 | B24: 71567890 | C24: Paola Andrea | D24: Martínez Guzmán | E24: 2025-11-15 | F24: =RANDBETWEEN(1,18) -> 16 | G24: F | H24: Síndrome de Asperger | I24: Centro TEA Tumbes | J24: Tumbes | K24: Tumbes | L24: 1 | M24: 3 | N24: 28 | O24: 15 | P24: 3 | Q24: =O24/(O24+P24)*100 -> 83.333333 | R24: 6.7 | S24: Medio | T24: 2 | U24: 40.7 | V24: Neutral | W24: 5 | X24: 5 | Y24: No | Z24: Requirió apoyo adicional del terapeuta
A25: P014 | B25: 71567890 | C25: Paola Andrea | D25: Martínez Guzmán | E25: 2025-11-03 | F25: =RANDBETWEEN(1,18) -> 14 | G25: F | H25: Síndrome de Asperger | I25: Centro TEA Tumbes | J25: Tumbes | K25: Tumbes | L25: 2 | M25: 3 | N25: 45 | O25: 13 | P25: 3 | Q25: =O25/(O25+P25)*100 -> 81.25 | R25: 6 | S25: Medio | T25: 2.2 | U25: 74.3 | V25: Disgustado | W25: 5 | X25: 5 | Y25: No | Z25: Excelente progreso en reconocimiento emocional
A26: P014 | B26: 71567890 | C26: Paola Andrea | D26: Martínez Guzmán | E26: 2025-11-13 | F26: =RANDBETWEEN(1,18) -> 18 | G26: F | H26: Síndrome de Asperger | I26: Centro TEA Tumbes | J26: Tumbes | K26: Tumbes | L26: 3 | M26: 3 | N26: 34 | O26: 11 | P26: 6 | Q26: =O26/(O26+P26)*100 -> 64.705882 | R26: 6.4 | S26: Medio | T26: 2 | U26: 74.6 | V26: Feliz | W26: 4 | X26: 3 | Y26: Sí | Z26: Mostró gran interés en la actividad
A27: P015 | B27: 73678901 | C27: Ricardo Manuel | D27: Espinoza León | E27: 2025-11-11 | F27: =RANDBETWEEN(1,18) -> 10 | G27: M | H27: TEA Nivel 1 | I27: Centro TEA San Juan de la Virgen | J27: Tumbes | K27: San Juan de la Virgen | L27: 1 | M27: 1 | N27: 26 | O27: 17 | P27: 5 | Q27: =O27/(O27+P27)*100 -> 77.272727 | R27: 4.5 | S27: Fácil | T27: 3.1 | U27: 43.5 | V27: Enojado | W27: 5 | X27: 4 | Y27: Sí | Z27: Excelente progreso en reconocimiento emocional
A28: P016 | B28: 74789012 | C28: Verónica Esther | D28: Campos Arteaga | E28: 2025-11-07 | F28: =RANDBETWEEN(1,18) -> 9 | G28: F | H28: TEA Nivel 2 | I28: Centro TEA Tumbes | J28: Tumbes | K28: Tumbes | L28: 1 | M28: 1 | N28: 31 | O28: 8 | P28: 9 | Q28: =O28/(O28+P28)*100 -> 47.058824 | R28: 5.7 | S28: Medio | T28: 2.7 | U28: 59.8 | V28: Neutral | W28: 4 | X28: 4 | Y28: Sí | Z28: Comprensión clara de las instrucciones
... A33: P020 | B33: 74123456 | C33: Diana Carolina | D33: Cabrera Montoya | E33: 2025-11-10 | F33: =RANDBETWEEN(1,18) -> 15 | G33: F | H33: TEA Nivel 2 | I33: Centro TEA Tumbes | J33: Tumbes | K33: Tumbes | L33: 1 | M33: 3 | N33: 34 | O33: 12 | P33: 4 | Q33: =O33/(O33+P33)*100 -> 75 | R33: 5.1 | S33: Difícil | T33: 1.8 | U33: 66.8 | V33: Disgustado | W33: 4 | X33: 5 | Y33: Sí | Z33: Requirió apoyo adicional del terapeuta
A34: P020 | B34: 74123456 | C34: Diana Carolina | D34: Cabrera Montoya | E34: 2025-11-13 | F34: =RANDBETWEEN(1,18) -> 4 | G34: F | H34: TEA Nivel 2 | I34: Centro TEA Tumbes | J34: Tumbes | K34: Tumbes | L34: 2 | M34: 3 | N34: 27 | O34: 13 | P34: 9 | Q34: =O34/(O34+P34)*100 -> 59.090909 | R34: 5.9 | S34: Medio | T34: 2.7 | U34: 53.3 | V34: Feliz | W34: 5 | X34: 4 | Y34: Sí
A35: P020 | B35: 74123456 | C35: Diana Carolina | D35: Cabrera Montoya | E35: 2025-11-03 | F35: =RANDBETWEEN(1,18) -> 5 | G35: F | H35: TEA Nivel 2 | I35: Centro TEA Tumbes | J35: Tumbes | K35: Tumbes | L35: 3 | M35: 3 | N35: 39 | O35: 13 | P35: 9 | Q35: =O35/(O35+P35)*100 -> 59.090909 | R35: 6.5 | S35: Medio | T35: 2.7 | U35: 48.6 | V35: Triste | W35: 3 | X35: 4 | Y35: No | Z35: Buena concentración durante toda la sesión
A36: P021 | B36: 72234567 | C36: Arturo Enrique | D36: Gutiérrez Ochoa | E36: 2025-11-14 | F36: =RANDBETWEEN(1,18) -> 5 | G36: M | H36: TEA Nivel 1 | I36: Centro TEA Zarumilla | J36: Tumbes | K36: Zarumilla | L36: 1 | M36: 3 | N36: 42 | O36: 14 | P36: 5 | Q36: =O36/(O36+P36)*100 -> 73.684211 | R36: 7.4 | S36: Fácil | T36: 1.8 | U36: 56 | V36: Triste | W36: 4 | X36: 3 | Y36: No | Z36: Dificultad con emociones complejas
A37: P021 | B37: 72234567 | C37: Arturo Enrique | D37: Gutiérrez Ochoa | E37: 2025-11-14 | F37: =RANDBETWEEN(1,18) -> 9 | G37: M | H37: TEA Nivel 1 | I37: Centro TEA Zarumilla | J37: Tumbes | K37: Zarumilla | L37: 2 | M37: 3 | N37: 41 | O37: 18 | P37: 3 | Q37: =O37/(O37+P37)*100 -> 85.714286 | R37: 5.2 | S37: Fácil | T37: 2.3 | U37: 63.6 | V37: Disgustado | W37: 5 | X37: 4 | Y37: Sí | Z37: Mostró gran interés en la actividad
A38: P021 | B38: 72234567 | C38: Arturo Enrique | D38: Gutiérrez Ochoa | E38: 2025-11-06 | F38: =RANDBETWEEN(1,18) -> 3 | G38: M | H38: TEA Nivel 1 | I38: Centro TEA Zarumilla | J38: Tumbes | K38: Zarumilla | L38: 3 | M38: 3 | N38: 35 | O38: 12 | P38: 3 | Q38: =O38/(O38+P38)*100 -> 80 | R38: 5.4 | S38: Fácil | T38: 1.6 | U38: 78.6 | V38: Neutral | W38: 4 | X38: 4 | Y38: Sí | Z38: Muy motivado con el formato de juego
A39: P022 | B39: 71345678 | C39: Fiorella Vanessa | D39: Romero Dávila | E39: 2025-11-01 | F39: =RANDBETWEEN(1,18) -> 17 | G39: F | H39: Síndrome de Asperger | I39: Centro TEA Tumbes | J39: Tumbes | K39: Tumbes | L39: 1 | M39: 1 | N39: 39 | O39: 11 | P39: 6 | Q39: =O39/(O39+P39)*100 -> 64.705882 | R39: 3.8 | S39: Medio | T39: 2 | U39: 73.1 | V39: Enojado | W39: 3 | X39: 5 | Y39: Sí | Z39: Dificultad con emociones complejas
A40: P023 | B40: 73456790 | C40: Alfredo Santiago | D40: Luna Benites | E40: 2025-11-14 | F40: =RANDBETWEEN(1,18) -> 12 | G40: M | H40: TEA Nivel 3 | I40: Centro TEA San Jacinto | J40: Tumbes | K40: San Jacinto | L40: 1 | M40: 2 | N40: 35 | O40: 9 | P40: 9 | Q40: =O40/(O40+P40)*100 -> 50 | R40: 7.1 | S40: Medio | T40: 2.1 | U40: 62.9 | V40: Neutral | W40: 3 | X40: 4 | Y40: No | Z40: Se distrajo en algunos momentos
A41: P023 | B41: 73456790 | C41: Alfredo Santiago | D41: Luna Benites | E41: 2025-11-02 | F41: =RANDBETWEEN(1,18) -> 15 | G41: M | H41: TEA Nivel 3 | I41: Centro TEA San Jacinto | J41: Tumbes | K41: San Jacinto | L41: 2 | M41: 2 | N41: 34 | O41: 8 | P41: 12 | Q41: =O41/(O41+P41)*100 -> 40 | R41: 6.7 | S41: Difícil | T41: 1.5 | U41: 77.7 | V41: Disgustado | W41: 5 | X41: 3 | Y41: No | Z41: Excelente progreso en reconocimiento emocional
A42: P024 | B42: 74567891 | C42: Claudia Stefany | D42: Jiménez Cruz | E42: 2025-10-30 | F42: =RANDBETWEEN(1,18) -> 5 | G42: F | H42: TEA Nivel 1 | I42: Centro TEA Tumbes | J42: Tumbes | K42: Tumbes | L42: 1 | M42: 2 | N42: 45 | O42: 14 | P42: 6 | Q42: =O42/(O42+P42)*100 -> 70 | R42: 7.8 | S42: Fácil | T42: 1.3 | U42: 78.1 | V42: Enojado | W42: 3 | X42: 5 | Y42: No | Z42: Excelente progreso en reconocimiento emocional
A43: P024 | B43: 74567891 | C43: Claudia Stefany | D43: Jiménez Cruz | E43: 2025-11-04 | F43: =RANDBETWEEN(1,18) -> 13 | G43: F | H43: TEA Nivel 1 | I43: Centro TEA Tumbes | J43: Tumbes | K43: Tumbes | L43: 2 | M43: 2 | N43: 37 | O43: 14 | P43: 3 | Q43: =O43/(O43+P43)*100 -> 82.352941 | R43: 7.5 | S43: Medio | T43: 3.2 | U43: 46.5 | V43: Neutral | W43: 4 | X43: 4 | Y43: Sí | Z43: Dificultad con emociones complejas
A44: P025 | B44: 72678902 | C44: Hugo Ramiro | D44: Vásquez Peña | E44: 2025-11-03 | F44: =RANDBETWEEN(1,18) -> 14 | G44: M | H44: TEA Nivel 2 | I44: Centro TEA Aguas Verdes | J44: Zarumilla | K44: Aguas Verdes | L44: 1 | M44: 1 | N44: 32 | O44: 12 | P44: 6 | Q44: =O44/(O44+P44)*100 -> 66.666667 | R44: 6 | S44: Difícil | T44: 2.3 | U44: 75.1 | V44: Triste | W44: 4 | X44: 4 | Y44: Sí | Z44: Dificultad con emociones complejas
...

Sheet Estadísticas
A1: RESUMEN ESTADÍSTICO
A3: Métrica | B3: Valor | C3: Fórmula | D3: Descripción
A4: Total Participantes | B4: 49 | C4: Cuenta participantes únicos | D4: Número total de personas que completaron pruebas
A5: Edad Promedio | B5: =AVERAGE('Datos Participantes'!F2:F200) -> 9.0506329 | C5: Promedio de edades | D5: Edad media de los participantes
A6: Precisión Promedio (%) | B6: =AVERAGE('Datos Participantes'!Q2:Q200) -> 67.487346 | C6: Promedio de precisión | D6: Efectividad promedio en reconocimiento
A7: Duración Promedio (min) | B7: =AVERAGE('Datos Participantes'!N2:N200) -> 35.797468 | C7: Tiempo promedio de sesión | D7: Duración media de uso de la app
A8: Satisfacción Promedio | B8: =AVERAGE('Datos Participantes'!W2:W200) -> 4.1265823 | C8: Promedio satisfacción (1-5) | D8: Nivel promedio de satisfacción
A9: Facilidad Uso Promedio | B9: =AVERAGE('Datos Participantes'!X2:X200) -> 4.1012658 | C9: Promedio facilidad (1-5) | D9: Percepción de facilidad de uso
A10: % Continuaría Usando | B10: =COUNTIF('Datos Participantes'!Y2:Y200,"Sí")/COUNTA('Datos Participantes'!Y2:Y200)*100 -> 70.886076 | C10: Porcentaje disposición a continuar | D10: Porcentaje que seguiría usando la app
A11: Emoción predominante más frecuente | B11: Neutral | C11: Moda de columna | D11: Emoción más común detectada en participantes
A13: DISTRIBUCIÓN DE EMOCIÓN PREDOMINANTE
A15: Emoción | B15: Frecuencia | C15: Porcentaje
A16: Feliz | B16: =COUNTIF('Datos Participantes'!V:V,"Feliz") -> 14 | C16: =COUNTIF('Datos Participantes'!V:V,"Feliz")/COUNTA('Datos Participantes'!V2:V200)*100 -> 17.721519
A17: Neutral | B17: =COUNTIF('Datos Participantes'!V:V,"Neutral") -> 19 | C17: =COUNTIF('Datos Participantes'!V:V,"Neutral")/COUNTA('Datos Participantes'!V2:V200)*100 -> 24.050633
A18: Triste | B18: =COUNTIF('Datos Participantes'!V:V,"Triste") -> 14 | C18: =COUNTIF('Datos Participantes'!V:V,"Triste")/COUNTA('Datos Participantes'!V2:V200)*100 -> 17.721519
A19: Enojado | B19: =COUNTIF('Datos Participantes'!V:V,"Enojado") -> 17 | C19: =COUNTIF('Datos Participantes'!V:V,"Enojado")/COUNTA('Datos Participantes'!V2:V200)*100 -> 21.518987
A20: Disgustado | B20: =COUNTIF('Datos Participantes'!V:V,"Disgustado") -> 15 | C20: =COUNTIF('Datos Participantes'!V:V,"Disgustado")/COUNTA('Datos Participantes'!V2:V200)*100 -> 18.987342
A21: TOTAL | B21: =SUM(B16:B20) -> 79 | C21: =SUM(C16:C20) -> 100

Sheet Diccionario Datos
A1: DICCIONARIO DE DATOS
A3: Campo | B3: Tipo | C3: Valores Permitidos | D3: Descripción
A4: ID_Participante | B4: Texto | C4: P001-P050 | D4: Código único anónimo del participante
A5: DNI | B5: Texto | C5: 8 dígitos | D5: Documento Nacional de Identidad (uso interno)
A6: Nombres | B6: Texto | C6: Texto libre | D6: Nombres del participante
A7: Apellidos | B7: Texto | C7: Texto libre | D7: Apellidos del participante
A8: Fecha_Prueba | B8: Fecha | C8: YYYY-MM-DD | D8: Fecha en que se realizó la sesión
A9: Edad | B9: Número | C9: 18-60 | D9: Edad del participante en años
A10: Sexo | B10: Texto | C10: M, F | D10: Sexo del participante
A11: Nivel_TEA | B11: Texto | C11: TEA Nivel 1/2/3, Síndrome de Asperger | D11: Nivel diagnosticado del TEA
A12: Institucion | B12: Texto | C12: Texto libre | D12: Nombre del centro donde se realizó
A13: Ciudad | B13: Texto | C13: Tumbes, Lima, etc | D13: Provincia donde se realizó la prueba
A14: Distrito | B14: Texto | C14: Texto libre | D14: Distrito específico
... A29: Observaciones | B29: Texto | C29: Texto libre | D29: Comentarios del participante, terapeuta o evaluador
